nohup: ignoring input
2020-11-15 01:36:16,595 log.py                     [line:117] INFO Task parrots_test_weekly_20201115_005603 have been started...
2020-11-15 01:36:16,596 log.py                     [line:117] INFO pavi tasks have been added to compare: 
2020-11-15 01:36:16,597 log.py                     [line:117] INFO http://pavi.parrots.sensetime.com/#/compare/904941fa-2480-4c90-b158-53ea58b4a983
2020-11-15 01:36:16,597 log.py                     [line:117] INFO 
2020-11-15 01:36:16,597 log.py                     [line:117] INFO ##############################
2020-11-15 01:36:16,597 log.py                     [line:117] INFO Now open a new terminal, and try ```search-ctl```command to manage your task
2020-11-15 01:36:16,598 log.py                     [line:117] INFO Please do not close this window and just enjoy
2020-11-15 01:36:16,598 log.py                     [line:117] INFO ##############################
2020-11-15 01:37:34,808 log.py                     [line:117] INFO Job(0)[pid: 14749][slurm: 1196252 PD]: sh runner/seg/train.sh pat_weeklybuild 16 pspnet --pavi --pavi-project parrots_test_weekly --data_reader MemcachedReader 
              with log: /mnt/lustre/parrots.tester.s.02/parrots_weekly/.search-run/tasks/parrots_test_weekly_20201115_005603/jobs/all/0/log
2020-11-15 01:37:49,609 log.py                     [line:117] INFO Job(0)[pid: 14749][slurm: 1196252] JobStatus.RUNNING: sh runner/seg/train.sh pat_weeklybuild 16 pspnet --pavi --pavi-project parrots_test_weekly --data_reader MemcachedReader 
                  with log: /mnt/lustre/parrots.tester.s.02/parrots_weekly/.search-run/tasks/parrots_test_weekly_20201115_005603/jobs/all/0/log
2020-11-15 01:38:15,225 log.py                     [line:117] INFO Job(1)[pid: 16625][slurm: 1196253 PD]: sh runner/example/train.sh pat_weeklybuild 8 mobile_v2_mix --pavi --pavi-project parrots_test_weekly --data_reader MemcachedReader 
              with log: /mnt/lustre/parrots.tester.s.02/parrots_weekly/.search-run/tasks/parrots_test_weekly_20201115_005603/jobs/all/1/log
2020-11-15 01:38:34,038 log.py                     [line:117] INFO Job(1)[pid: 16625][slurm: 1196253] JobStatus.RUNNING: sh runner/example/train.sh pat_weeklybuild 8 mobile_v2_mix --pavi --pavi-project parrots_test_weekly --data_reader MemcachedReader 
                  with log: /mnt/lustre/parrots.tester.s.02/parrots_weekly/.search-run/tasks/parrots_test_weekly_20201115_005603/jobs/all/1/log
2020-11-15 01:38:55,442 log.py                     [line:117] INFO Job(2)[pid: 18424][slurm: 1196254 PD]: sh runner/example/train.sh pat_weeklybuild 8 shuffle_v2_mix --pavi --pavi-project parrots_test_weekly --data_reader MemcachedReader 
              with log: /mnt/lustre/parrots.tester.s.02/parrots_weekly/.search-run/tasks/parrots_test_weekly_20201115_005603/jobs/all/2/log
2020-11-15 01:39:12,575 log.py                     [line:117] INFO Job(2)[pid: 18424][slurm: 1196254] JobStatus.RUNNING: sh runner/example/train.sh pat_weeklybuild 8 shuffle_v2_mix --pavi --pavi-project parrots_test_weekly --data_reader MemcachedReader 
                  with log: /mnt/lustre/parrots.tester.s.02/parrots_weekly/.search-run/tasks/parrots_test_weekly_20201115_005603/jobs/all/2/log
2020-11-15 01:39:37,788 log.py                     [line:117] INFO Job(3)[pid: 20204][slurm: 1196255 PD]: sh runner/mmaction/train.sh pat_weeklybuild 8 i3d_r50_video_32x2x1_100e_kinetics400_rgb --pavi --pavi-project parrots_test_weekly --data_reader MemcachedReader --seed 1024 
              with log: /mnt/lustre/parrots.tester.s.02/parrots_weekly/.search-run/tasks/parrots_test_weekly_20201115_005603/jobs/all/3/log
2020-11-15 01:39:54,744 log.py                     [line:117] INFO Job(3)[pid: 20204][slurm: 1196255] JobStatus.RUNNING: sh runner/mmaction/train.sh pat_weeklybuild 8 i3d_r50_video_32x2x1_100e_kinetics400_rgb --pavi --pavi-project parrots_test_weekly --data_reader MemcachedReader --seed 1024 
                  with log: /mnt/lustre/parrots.tester.s.02/parrots_weekly/.search-run/tasks/parrots_test_weekly_20201115_005603/jobs/all/3/log
2020-11-15 01:40:23,148 log.py                     [line:117] INFO Job(4)[pid: 22613][slurm: 1196256 PD]: sh runner/example/train.sh pat_weeklybuild 8 inception_v4_mix --pavi --pavi-project parrots_test_weekly --data_reader MemcachedReader 
              with log: /mnt/lustre/parrots.tester.s.02/parrots_weekly/.search-run/tasks/parrots_test_weekly_20201115_005603/jobs/all/4/log
2020-11-15 01:41:08,723 log.py                     [line:117] INFO Job(5)[pid: 24531][slurm: 1196257 PD]: sh runner/mmaction/train.sh pat_weeklybuild 8 tsn_r50_video_1x1x8_100e_kinetics400_rgb --pavi --pavi-project parrots_test_weekly --data_reader MemcachedReader --seed 1024 
              with log: /mnt/lustre/parrots.tester.s.02/parrots_weekly/.search-run/tasks/parrots_test_weekly_20201115_005603/jobs/all/5/log
2020-11-15 01:41:54,872 log.py                     [line:117] INFO Job(6)[pid: 30196][slurm: 1196258 PD]: sh runner/mmdet/train.sh pat_weeklybuild 8 mask_rcnn_x101_32x4d_fpn_1x_coco --pavi --pavi-project parrots_test_weekly --seed 1024 
              with log: /mnt/lustre/parrots.tester.s.02/parrots_weekly/.search-run/tasks/parrots_test_weekly_20201115_005603/jobs/all/6/log
2020-11-15 01:42:41,249 log.py                     [line:117] INFO Job(7)[pid: 32405][slurm: 1196259 PD]: sh runner/mmediting/train.sh pat_weeklybuild 8 gl_256x256_8x12_celeba --pavi --pavi-project parrots_test_weekly --data-reader MemcachedReader --seed 1024 
              with log: /mnt/lustre/parrots.tester.s.02/parrots_weekly/.search-run/tasks/parrots_test_weekly_20201115_005603/jobs/all/7/log
2020-11-15 01:43:23,073 log.py                     [line:117] INFO Job(8)[pid: 34354][slurm: 1196261 PD]: sh runner/seg_nas/train.sh pat_weeklybuild 8 single_path_oneshot --pavi --pavi-project parrots_test_weekly --data_reader MemcachedReader --seed 1024 
              with log: /mnt/lustre/parrots.tester.s.02/parrots_weekly/.search-run/tasks/parrots_test_weekly_20201115_005603/jobs/all/8/log
2020-11-15 01:44:04,910 log.py                     [line:117] INFO Job(9)[pid: 36081][slurm: 1196262 PD]: sh runner/mmdet/train.sh pat_weeklybuild 8 faster_rcnn_r50_fpn_1x_coco --pavi --pavi-project parrots_test_weekly --seed 1024 
              with log: /mnt/lustre/parrots.tester.s.02/parrots_weekly/.search-run/tasks/parrots_test_weekly_20201115_005603/jobs/all/9/log
2020-11-15 01:44:47,659 log.py                     [line:117] INFO Job(10)[pid: 37962][slurm: 1196263 PD]: sh runner/example/train.sh pat_weeklybuild 8 se_resnet50 --pavi --pavi-project parrots_test_weekly --data_reader MemcachedReader 
              with log: /mnt/lustre/parrots.tester.s.02/parrots_weekly/.search-run/tasks/parrots_test_weekly_20201115_005603/jobs/all/10/log
2020-11-15 01:45:27,631 log.py                     [line:117] INFO Job(11)[pid: 40644][slurm: 1196264 PD]: sh runner/mmdet/train.sh pat_weeklybuild 8 retinanet_r50_fpn_fp16_1x_coco --pavi --pavi-project parrots_test_weekly --seed 1024 
              with log: /mnt/lustre/parrots.tester.s.02/parrots_weekly/.search-run/tasks/parrots_test_weekly_20201115_005603/jobs/all/11/log
2020-11-15 01:46:10,715 log.py                     [line:117] INFO Job(12)[pid: 42849][slurm: 1196265 PD]: sh runner/pod/train.sh pat_weeklybuild 8 keypoint-rcnn-R50-FPN-1x_mix --pavi --pavi-project parrots_test_weekly 
              with log: /mnt/lustre/parrots.tester.s.02/parrots_weekly/.search-run/tasks/parrots_test_weekly_20201115_005603/jobs/all/12/log
2020-11-15 01:46:54,986 log.py                     [line:117] INFO Job(13)[pid: 45094][slurm: 1196266 PD]: sh runner/alphatrion_nas/train.sh pat_weeklybuild 8 super_resnet_range1 --pavi.use true --pavi.writer.project parrots_test_weekly --data_reader MemcachedReader --seed 1024 
              with log: /mnt/lustre/parrots.tester.s.02/parrots_weekly/.search-run/tasks/parrots_test_weekly_20201115_005603/jobs/all/13/log
2020-11-15 01:47:35,892 log.py                     [line:117] INFO Job(14)[pid: 47364][slurm: 1196267 PD]: sh runner/alphatrion/train.sh pat_weeklybuild 8 mobilenet_v2_fp16 --pavi.use true --pavi.writer.project parrots_test_weekly --data_reader MemcachedReader --seed 1024 
              with log: /mnt/lustre/parrots.tester.s.02/parrots_weekly/.search-run/tasks/parrots_test_weekly_20201115_005603/jobs/all/14/log
2020-11-15 01:48:14,876 log.py                     [line:117] INFO Job(15)[pid: 49915][slurm: 1196269 PD]: sh runner/alphatrion/train.sh pat_weeklybuild 8 mobilenet_v2_fp32 --pavi.use true --pavi.writer.project parrots_test_weekly --data_reader MemcachedReader --seed 1024 
              with log: /mnt/lustre/parrots.tester.s.02/parrots_weekly/.search-run/tasks/parrots_test_weekly_20201115_005603/jobs/all/15/log
2020-11-15 01:48:55,979 log.py                     [line:117] INFO Job(16)[pid: 52394][slurm: 1196270 PD]: sh runner/alphatrion/train.sh pat_weeklybuild 8 resnet101_fp16 --pavi.use true --pavi.writer.project parrots_test_weekly --data_reader MemcachedReader --seed 1024 
              with log: /mnt/lustre/parrots.tester.s.02/parrots_weekly/.search-run/tasks/parrots_test_weekly_20201115_005603/jobs/all/16/log
2020-11-15 01:49:36,029 log.py                     [line:117] INFO Job(17)[pid: 54975][slurm: 1196271 PD]: sh runner/alphatrion_nas/train.sh pat_weeklybuild 8 super_resnet_range1_fp16 --pavi.use true --pavi.writer.project parrots_test_weekly --data_reader MemcachedReader --seed 1024 
              with log: /mnt/lustre/parrots.tester.s.02/parrots_weekly/.search-run/tasks/parrots_test_weekly_20201115_005603/jobs/all/17/log
2020-11-15 01:50:14,973 log.py                     [line:117] INFO Job(18)[pid: 57883][slurm: 1196272 PD]: sh runner/pod/train.sh pat_weeklybuild 8 mask-rcnn-R50-FPN-1x_mix --pavi --pavi-project parrots_test_weekly --seed 1024 
              with log: /mnt/lustre/parrots.tester.s.02/parrots_weekly/.search-run/tasks/parrots_test_weekly_20201115_005603/jobs/all/18/log
2020-11-15 01:50:55,708 log.py                     [line:117] INFO Job(19)[pid: 60445][slurm: 1196273 PD]: sh runner/pod/train.sh pat_weeklybuild 8 faster-rcnn-R50-FPN-1x_mix --pavi --pavi-project parrots_test_weekly --seed 1024 
              with log: /mnt/lustre/parrots.tester.s.02/parrots_weekly/.search-run/tasks/parrots_test_weekly_20201115_005603/jobs/all/19/log
2020-11-15 01:51:35,475 log.py                     [line:117] INFO Job(20)[pid: 63089][slurm: 1196275 PD]: sh runner/pod/train.sh pat_weeklybuild 8 retinanet-R50-1x --pavi --pavi-project parrots_test_weekly --seed 1024 
              with log: /mnt/lustre/parrots.tester.s.02/parrots_weekly/.search-run/tasks/parrots_test_weekly_20201115_005603/jobs/all/20/log
Traceback (most recent call last):
  File "autotest/parrots_test_callback_new.py", line 652, in <module>
    pre_callback_wrapper(config, sys.argv[4], sys.argv[1], sys.argv[2])
  File "autotest/parrots_test_callback_new.py", line 627, in pre_callback_wrapper
    _watch_for_kill_time_limited(framework, model, config)
  File "autotest/parrots_test_callback_new.py", line 127, in _watch_for_kill_time_limited
    filter(lambda j: j['name'] in [name], info['jobs']))
TypeError: 'NoneType' object is not subscriptable
2020-11-15 01:52:15,446 log.py                     [line:117] INFO Job(21)[pid: 65738][slurm: 1196276 PD]: sh runner/mmdet/train.sh pat_weeklybuild 8 mask_rcnn_x101_64x4d_fpn_1x_coco --pavi --pavi-project parrots_test_weekly --seed 1024 
              with log: /mnt/lustre/parrots.tester.s.02/parrots_weekly/.search-run/tasks/parrots_test_weekly_20201115_005603/jobs/all/21/log
2020-11-15 01:52:58,160 log.py                     [line:117] INFO Job(22)[pid: 68391][slurm: 1196278 PD]: sh runner/alphatrion/train.sh pat_weeklybuild 8 resnet101_fp32 --pavi.use true --pavi.writer.project parrots_test_weekly --data_reader MemcachedReader --seed 1024 
              with log: /mnt/lustre/parrots.tester.s.02/parrots_weekly/.search-run/tasks/parrots_test_weekly_20201115_005603/jobs/all/22/log
2020-11-15 01:53:36,463 log.py                     [line:117] INFO Job(23)[pid: 71089][slurm: 1196279 PD]: sh runner/alphatrion/train.sh pat_weeklybuild 8 resnet50_fp16 --pavi.use true --pavi.writer.project parrots_test_weekly --data_reader MemcachedReader --seed 1024 
              with log: /mnt/lustre/parrots.tester.s.02/parrots_weekly/.search-run/tasks/parrots_test_weekly_20201115_005603/jobs/all/23/log
2020-11-15 01:54:17,566 log.py                     [line:117] INFO Job(24)[pid: 73666][slurm: 1196280 PD]: sh runner/mmdet/train.sh pat_weeklybuild 8 faster_rcnn_r50_fpn_dconv_c3-c5_1x_coco --pavi --pavi-project parrots_test_weekly --seed 1024 
              with log: /mnt/lustre/parrots.tester.s.02/parrots_weekly/.search-run/tasks/parrots_test_weekly_20201115_005603/jobs/all/24/log
2020-11-15 01:54:54,499 log.py                     [line:117] INFO Job(25)[pid: 75942][slurm: 1196283 PD]: sh runner/pod/train.sh pat_weeklybuild 8 faster-rcnn-R50-FPN-1x-DCN@C3-C5 --pavi --pavi-project parrots_test_weekly 
              with log: /mnt/lustre/parrots.tester.s.02/parrots_weekly/.search-run/tasks/parrots_test_weekly_20201115_005603/jobs/all/25/log
2020-11-15 01:55:32,876 log.py                     [line:117] INFO Job(26)[pid: 78285][slurm: 1196284 PD]: sh runner/mmdet/train.sh pat_weeklybuild 8 mask_rcnn_r50_caffe_fpn_mstrain_1x_coco --pavi --pavi-project parrots_test_weekly --seed 1024 
              with log: /mnt/lustre/parrots.tester.s.02/parrots_weekly/.search-run/tasks/parrots_test_weekly_20201115_005603/jobs/all/26/log
Traceback (most recent call last):
  File "autotest/parrots_test_callback_new.py", line 652, in <module>
    pre_callback_wrapper(config, sys.argv[4], sys.argv[1], sys.argv[2])
  File "autotest/parrots_test_callback_new.py", line 627, in pre_callback_wrapper
    _watch_for_kill_time_limited(framework, model, config)
  File "autotest/parrots_test_callback_new.py", line 127, in _watch_for_kill_time_limited
    filter(lambda j: j['name'] in [name], info['jobs']))
TypeError: 'NoneType' object is not subscriptable
2020-11-15 01:56:15,106 log.py                     [line:117] INFO Job(27)[pid: 80851][slurm: 1196285 PD]: sh runner/mmdet/train.sh pat_weeklybuild 8 cascade_mask_rcnn_r50_fpn_1x_coco --pavi --pavi-project parrots_test_weekly --seed 1024 
              with log: /mnt/lustre/parrots.tester.s.02/parrots_weekly/.search-run/tasks/parrots_test_weekly_20201115_005603/jobs/all/27/log
2020-11-15 01:56:55,953 log.py                     [line:117] INFO Job(28)[pid: 87197][slurm: 1196286 PD]: sh runner/mmdet/train.sh pat_weeklybuild 8 mask_rcnn_r101_fpn_1x_coco --pavi --pavi-project parrots_test_weekly --seed 1024 
              with log: /mnt/lustre/parrots.tester.s.02/parrots_weekly/.search-run/tasks/parrots_test_weekly_20201115_005603/jobs/all/28/log
2020-11-15 01:57:36,764 log.py                     [line:117] INFO Job(29)[pid: 89814][slurm: 1196287 PD]: sh runner/alphatrion/train.sh pat_weeklybuild 8 se_resnet50_fp16 --pavi.use true --pavi.writer.project parrots_test_weekly --data_reader MemcachedReader --seed 1024 
              with log: /mnt/lustre/parrots.tester.s.02/parrots_weekly/.search-run/tasks/parrots_test_weekly_20201115_005603/jobs/all/29/log
2020-11-15 01:58:11,310 log.py                     [line:117] INFO len of threads: 31
2020-11-15 01:58:16,405 log.py                     [line:117] INFO Job(30)[pid: 92610][slurm: 1196292 PD]: sh runner/alphatrion/train.sh pat_weeklybuild 8 se_resnet50_fp32 --pavi.use true --pavi.writer.project parrots_test --data_reader MemcachedReader --seed 1024 
              with log: /mnt/lustre/parrots.tester.s.02/parrots_weekly/.search-run/tasks/parrots_test_weekly_20201115_005603/jobs/all/30/log
2020-11-15 04:59:29,977 ERROR: get_compare error [RequestError: Forbidden]
Exception in thread Thread-32:
Traceback (most recent call last):
  File "/mnt/cache/share/platform/env/miniconda3.6/envs/pat20201113/lib/python3.6/threading.py", line 916, in _bootstrap_inner
    self.run()
  File "/mnt/cache/share/platform/env/miniconda3.6/envs/pat20201113/lib/python3.6/threading.py", line 864, in run
    self._target(*self._args, **self._kwargs)
  File "/mnt/cache/share/platform/env/miniconda3.6/envs/pat20201113/lib/python3.6/site-packages/autoparrots-1.0rc1+fbf1439-py3.6.egg/autoparrots/schedulers/base_scheduler.py", line 187, in _run_job
    task = pavi_get_task(self.pavi_compare_id, job.id)
  File "/mnt/cache/share/platform/env/miniconda3.6/envs/pat20201113/lib/python3.6/site-packages/autoparrots-1.0rc1+fbf1439-py3.6.egg/autoparrots/utils/pavi_helper.py", line 14, in pavi_get_task
    trainings = compare.get('trainings', [])
AttributeError: 'NoneType' object has no attribute 'get'

2020-11-15 04:59:31,530 ERROR: get_compare error [RequestError: Get http://auth.parrots.sensetime.com/api/v1/session: dial tcp: lookup auth.parrots.sensetime.com on 10.96.0.10:53: read udp 10.244.37.163:58109->10.96.0.10:53: read: connection refused]
2020-11-15 04:59:31,531 ERROR: get_compare error [RequestError: Get http://auth.parrots.sensetime.com/api/v1/session: dial tcp: lookup auth.parrots.sensetime.com on 10.96.0.10:53: read udp 10.244.37.163:58109->10.96.0.10:53: read: connection refused]
2020-11-15 04:59:31,532 ERROR: get_compare error [RequestError: Get http://auth.parrots.sensetime.com/api/v1/session: dial tcp: lookup auth.parrots.sensetime.com on 10.96.0.10:53: read udp 10.244.37.163:58109->10.96.0.10:53: read: connection refused]
2020-11-15 04:59:31,533 ERROR: get_compare error [RequestError: Get http://auth.parrots.sensetime.com/api/v1/session: dial tcp: lookup auth.parrots.sensetime.com on 10.96.0.10:53: read udp 10.244.37.163:58109->10.96.0.10:53: read: connection refused]
Exception in thread Thread-22:
Traceback (most recent call last):
  File "/mnt/cache/share/platform/env/miniconda3.6/envs/pat20201113/lib/python3.6/threading.py", line 916, in _bootstrap_inner
    self.run()
  File "/mnt/cache/share/platform/env/miniconda3.6/envs/pat20201113/lib/python3.6/threading.py", line 864, in run
    self._target(*self._args, **self._kwargs)
  File "/mnt/cache/share/platform/env/miniconda3.6/envs/pat20201113/lib/python3.6/site-packages/autoparrots-1.0rc1+fbf1439-py3.6.egg/autoparrots/schedulers/base_scheduler.py", line 187, in _run_job
    task = pavi_get_task(self.pavi_compare_id, job.id)
  File "/mnt/cache/share/platform/env/miniconda3.6/envs/pat20201113/lib/python3.6/site-packages/autoparrots-1.0rc1+fbf1439-py3.6.egg/autoparrots/utils/pavi_helper.py", line 14, in pavi_get_task
    trainings = compare.get('trainings', [])
AttributeError: 'NoneType' object has no attribute 'get'

2020-11-15 04:59:31,534 ERROR: get_compare error [RequestError: Get http://auth.parrots.sensetime.com/api/v1/session: dial tcp: lookup auth.parrots.sensetime.com on 10.96.0.10:53: read udp 10.244.37.163:58109->10.96.0.10:53: read: connection refused]
Exception in thread Thread-11:
Traceback (most recent call last):
  File "/mnt/cache/share/platform/env/miniconda3.6/envs/pat20201113/lib/python3.6/threading.py", line 916, in _bootstrap_inner
    self.run()
  File "/mnt/cache/share/platform/env/miniconda3.6/envs/pat20201113/lib/python3.6/threading.py", line 864, in run
    self._target(*self._args, **self._kwargs)
  File "/mnt/cache/share/platform/env/miniconda3.6/envs/pat20201113/lib/python3.6/site-packages/autoparrots-1.0rc1+fbf1439-py3.6.egg/autoparrots/schedulers/base_scheduler.py", line 187, in _run_job
    task = pavi_get_task(self.pavi_compare_id, job.id)
  File "/mnt/cache/share/platform/env/miniconda3.6/envs/pat20201113/lib/python3.6/site-packages/autoparrots-1.0rc1+fbf1439-py3.6.egg/autoparrots/utils/pavi_helper.py", line 14, in pavi_get_task
    trainings = compare.get('trainings', [])
AttributeError: 'NoneType' object has no attribute 'get'

2020-11-15 04:59:31,534 ERROR: get_scalar error [RequestError: Get http://auth.parrots.sensetime.com/api/v1/session: dial tcp: lookup auth.parrots.sensetime.com on 10.96.0.10:53: read udp 10.244.37.163:58109->10.96.0.10:53: read: connection refused]
Exception in thread Thread-24:
Traceback (most recent call last):
  File "/mnt/cache/share/platform/env/miniconda3.6/envs/pat20201113/lib/python3.6/threading.py", line 916, in _bootstrap_inner
    self.run()
  File "/mnt/cache/share/platform/env/miniconda3.6/envs/pat20201113/lib/python3.6/threading.py", line 864, in run
    self._target(*self._args, **self._kwargs)
  File "/mnt/cache/share/platform/env/miniconda3.6/envs/pat20201113/lib/python3.6/site-packages/autoparrots-1.0rc1+fbf1439-py3.6.egg/autoparrots/schedulers/base_scheduler.py", line 187, in _run_job
    task = pavi_get_task(self.pavi_compare_id, job.id)
  File "/mnt/cache/share/platform/env/miniconda3.6/envs/pat20201113/lib/python3.6/site-packages/autoparrots-1.0rc1+fbf1439-py3.6.egg/autoparrots/utils/pavi_helper.py", line 14, in pavi_get_task
    trainings = compare.get('trainings', [])
AttributeError: 'NoneType' object has no attribute 'get'

2020-11-15 04:59:31,535 ERROR: get_scalar error [RequestError: Get http://auth.parrots.sensetime.com/api/v1/session: dial tcp: lookup auth.parrots.sensetime.com on 10.96.0.10:53: read udp 10.244.37.163:58109->10.96.0.10:53: read: connection refused]
2020-11-15 04:59:31,536 ERROR: get_compare error [RequestError: Get http://auth.parrots.sensetime.com/api/v1/session: dial tcp: lookup auth.parrots.sensetime.com on 10.96.0.10:53: read udp 10.244.37.163:58109->10.96.0.10:53: read: connection refused]
2020-11-15 04:59:31,538 ERROR: get_compare error [RequestError: Get http://auth.parrots.sensetime.com/api/v1/session: dial tcp: lookup auth.parrots.sensetime.com on 10.96.0.10:53: read udp 10.244.37.163:58109->10.96.0.10:53: read: connection refused]
Exception in thread Thread-29:
Traceback (most recent call last):
  File "/mnt/cache/share/platform/env/miniconda3.6/envs/pat20201113/lib/python3.6/threading.py", line 916, in _bootstrap_inner
    self.run()
  File "/mnt/cache/share/platform/env/miniconda3.6/envs/pat20201113/lib/python3.6/threading.py", line 864, in run
    self._target(*self._args, **self._kwargs)
  File "/mnt/cache/share/platform/env/miniconda3.6/envs/pat20201113/lib/python3.6/site-packages/autoparrots-1.0rc1+fbf1439-py3.6.egg/autoparrots/schedulers/base_scheduler.py", line 187, in _run_job
    task = pavi_get_task(self.pavi_compare_id, job.id)
  File "/mnt/cache/share/platform/env/miniconda3.6/envs/pat20201113/lib/python3.6/site-packages/autoparrots-1.0rc1+fbf1439-py3.6.egg/autoparrots/utils/pavi_helper.py", line 14, in pavi_get_task
    trainings = compare.get('trainings', [])
AttributeError: 'NoneType' object has no attribute 'get'

Exception in thread Thread-35:
Traceback (most recent call last):
  File "/mnt/cache/share/platform/env/miniconda3.6/envs/pat20201113/lib/python3.6/threading.py", line 916, in _bootstrap_inner
    self.run()
  File "/mnt/cache/share/platform/env/miniconda3.6/envs/pat20201113/lib/python3.6/threading.py", line 864, in run
    self._target(*self._args, **self._kwargs)
  File "/mnt/cache/share/platform/env/miniconda3.6/envs/pat20201113/lib/python3.6/site-packages/autoparrots-1.0rc1+fbf1439-py3.6.egg/autoparrots/schedulers/base_scheduler.py", line 187, in _run_job
    task = pavi_get_task(self.pavi_compare_id, job.id)
  File "/mnt/cache/share/platform/env/miniconda3.6/envs/pat20201113/lib/python3.6/site-packages/autoparrots-1.0rc1+fbf1439-py3.6.egg/autoparrots/utils/pavi_helper.py", line 14, in pavi_get_task
    trainings = compare.get('trainings', [])
AttributeError: 'NoneType' object has no attribute 'get'

Exception in thread Thread-14:
Traceback (most recent call last):
  File "/mnt/cache/share/platform/env/miniconda3.6/envs/pat20201113/lib/python3.6/threading.py", line 916, in _bootstrap_inner
    self.run()
  File "/mnt/cache/share/platform/env/miniconda3.6/envs/pat20201113/lib/python3.6/threading.py", line 864, in run
    self._target(*self._args, **self._kwargs)
  File "/mnt/cache/share/platform/env/miniconda3.6/envs/pat20201113/lib/python3.6/site-packages/autoparrots-1.0rc1+fbf1439-py3.6.egg/autoparrots/schedulers/base_scheduler.py", line 187, in _run_job
    task = pavi_get_task(self.pavi_compare_id, job.id)
  File "/mnt/cache/share/platform/env/miniconda3.6/envs/pat20201113/lib/python3.6/site-packages/autoparrots-1.0rc1+fbf1439-py3.6.egg/autoparrots/utils/pavi_helper.py", line 14, in pavi_get_task
    trainings = compare.get('trainings', [])
AttributeError: 'NoneType' object has no attribute 'get'

Exception in thread Thread-37:
Traceback (most recent call last):
  File "/mnt/cache/share/platform/env/miniconda3.6/envs/pat20201113/lib/python3.6/threading.py", line 916, in _bootstrap_inner
    self.run()
  File "/mnt/cache/share/platform/env/miniconda3.6/envs/pat20201113/lib/python3.6/threading.py", line 864, in run
    self._target(*self._args, **self._kwargs)
  File "/mnt/cache/share/platform/env/miniconda3.6/envs/pat20201113/lib/python3.6/site-packages/autoparrots-1.0rc1+fbf1439-py3.6.egg/autoparrots/schedulers/base_scheduler.py", line 187, in _run_job
    task = pavi_get_task(self.pavi_compare_id, job.id)
  File "/mnt/cache/share/platform/env/miniconda3.6/envs/pat20201113/lib/python3.6/site-packages/autoparrots-1.0rc1+fbf1439-py3.6.egg/autoparrots/utils/pavi_helper.py", line 14, in pavi_get_task
    trainings = compare.get('trainings', [])
AttributeError: 'NoneType' object has no attribute 'get'

2020-11-15 04:59:31,731 ERROR: get_compare error [RequestError: Get http://auth.parrots.sensetime.com/api/v1/session: dial tcp: lookup auth.parrots.sensetime.com on 10.96.0.10:53: read udp 10.244.40.174:42160->10.96.0.10:53: read: connection refused]
2020-11-15 04:59:31,732 ERROR: get_compare error [RequestError: Get http://auth.parrots.sensetime.com/api/v1/session: dial tcp: lookup auth.parrots.sensetime.com on 10.96.0.10:53: read udp 10.244.40.174:42160->10.96.0.10:53: read: connection refused]
2020-11-15 04:59:31,732 ERROR: get_compare error [RequestError: Get http://auth.parrots.sensetime.com/api/v1/session: dial tcp: lookup auth.parrots.sensetime.com on 10.96.0.10:53: read udp 10.244.40.174:42160->10.96.0.10:53: read: connection refused]
2020-11-15 04:59:31,733 ERROR: get_scalar error [RequestError: Get http://auth.parrots.sensetime.com/api/v1/session: dial tcp: lookup auth.parrots.sensetime.com on 10.96.0.10:53: read udp 10.244.40.174:42160->10.96.0.10:53: read: connection refused]
2020-11-15 04:59:31,734 ERROR: get_compare error [RequestError: Get http://auth.parrots.sensetime.com/api/v1/session: dial tcp: lookup auth.parrots.sensetime.com on 10.96.0.10:53: read udp 10.244.40.174:42160->10.96.0.10:53: read: connection refused]
2020-11-15 04:59:31,735 ERROR: get_compare error [RequestError: Get http://auth.parrots.sensetime.com/api/v1/session: dial tcp: lookup auth.parrots.sensetime.com on 10.96.0.10:53: read udp 10.244.40.174:42160->10.96.0.10:53: read: connection refused]
Exception in thread Thread-15:
Traceback (most recent call last):
  File "/mnt/cache/share/platform/env/miniconda3.6/envs/pat20201113/lib/python3.6/threading.py", line 916, in _bootstrap_inner
    self.run()
  File "/mnt/cache/share/platform/env/miniconda3.6/envs/pat20201113/lib/python3.6/threading.py", line 864, in run
    self._target(*self._args, **self._kwargs)
  File "/mnt/cache/share/platform/env/miniconda3.6/envs/pat20201113/lib/python3.6/site-packages/autoparrots-1.0rc1+fbf1439-py3.6.egg/autoparrots/schedulers/base_scheduler.py", line 187, in _run_job
    task = pavi_get_task(self.pavi_compare_id, job.id)
  File "/mnt/cache/share/platform/env/miniconda3.6/envs/pat20201113/lib/python3.6/site-packages/autoparrots-1.0rc1+fbf1439-py3.6.egg/autoparrots/utils/pavi_helper.py", line 14, in pavi_get_task
    trainings = compare.get('trainings', [])
AttributeError: 'NoneType' object has no attribute 'get'

Exception in thread Thread-17:
Traceback (most recent call last):
  File "/mnt/cache/share/platform/env/miniconda3.6/envs/pat20201113/lib/python3.6/threading.py", line 916, in _bootstrap_inner
    self.run()
  File "/mnt/cache/share/platform/env/miniconda3.6/envs/pat20201113/lib/python3.6/threading.py", line 864, in run
    self._target(*self._args, **self._kwargs)
  File "/mnt/cache/share/platform/env/miniconda3.6/envs/pat20201113/lib/python3.6/site-packages/autoparrots-1.0rc1+fbf1439-py3.6.egg/autoparrots/schedulers/base_scheduler.py", line 187, in _run_job
    task = pavi_get_task(self.pavi_compare_id, job.id)
  File "/mnt/cache/share/platform/env/miniconda3.6/envs/pat20201113/lib/python3.6/site-packages/autoparrots-1.0rc1+fbf1439-py3.6.egg/autoparrots/utils/pavi_helper.py", line 14, in pavi_get_task
    trainings = compare.get('trainings', [])
AttributeError: 'NoneType' object has no attribute 'get'

2020-11-15 04:59:31,735 ERROR: get_compare error [RequestError: Get http://auth.parrots.sensetime.com/api/v1/session: dial tcp: lookup auth.parrots.sensetime.com on 10.96.0.10:53: read udp 10.244.40.174:42160->10.96.0.10:53: read: connection refused]
2020-11-15 04:59:31,736 ERROR: get_scalar error [RequestError: Get http://auth.parrots.sensetime.com/api/v1/session: dial tcp: lookup auth.parrots.sensetime.com on 10.96.0.10:53: read udp 10.244.40.174:42160->10.96.0.10:53: read: connection refused]
Exception in thread Thread-20:
Traceback (most recent call last):
  File "/mnt/cache/share/platform/env/miniconda3.6/envs/pat20201113/lib/python3.6/threading.py", line 916, in _bootstrap_inner
    self.run()
  File "/mnt/cache/share/platform/env/miniconda3.6/envs/pat20201113/lib/python3.6/threading.py", line 864, in run
    self._target(*self._args, **self._kwargs)
  File "/mnt/cache/share/platform/env/miniconda3.6/envs/pat20201113/lib/python3.6/site-packages/autoparrots-1.0rc1+fbf1439-py3.6.egg/autoparrots/schedulers/base_scheduler.py", line 187, in _run_job
    task = pavi_get_task(self.pavi_compare_id, job.id)
  File "/mnt/cache/share/platform/env/miniconda3.6/envs/pat20201113/lib/python3.6/site-packages/autoparrots-1.0rc1+fbf1439-py3.6.egg/autoparrots/utils/pavi_helper.py", line 14, in pavi_get_task
    trainings = compare.get('trainings', [])
AttributeError: 'NoneType' object has no attribute 'get'

Exception in thread Thread-36:
Traceback (most recent call last):
  File "/mnt/cache/share/platform/env/miniconda3.6/envs/pat20201113/lib/python3.6/threading.py", line 916, in _bootstrap_inner
    self.run()
  File "/mnt/cache/share/platform/env/miniconda3.6/envs/pat20201113/lib/python3.6/threading.py", line 864, in run
    self._target(*self._args, **self._kwargs)
  File "/mnt/cache/share/platform/env/miniconda3.6/envs/pat20201113/lib/python3.6/site-packages/autoparrots-1.0rc1+fbf1439-py3.6.egg/autoparrots/schedulers/base_scheduler.py", line 187, in _run_job
    task = pavi_get_task(self.pavi_compare_id, job.id)
  File "/mnt/cache/share/platform/env/miniconda3.6/envs/pat20201113/lib/python3.6/site-packages/autoparrots-1.0rc1+fbf1439-py3.6.egg/autoparrots/utils/pavi_helper.py", line 14, in pavi_get_task
    trainings = compare.get('trainings', [])
AttributeError: 'NoneType' object has no attribute 'get'

2020-11-15 04:59:31,737 ERROR: get_compare error [RequestError: Get http://auth.parrots.sensetime.com/api/v1/session: dial tcp: lookup auth.parrots.sensetime.com on 10.96.0.10:53: read udp 10.244.40.174:42160->10.96.0.10:53: read: connection refused]
Exception in thread Thread-13:
Traceback (most recent call last):
  File "/mnt/cache/share/platform/env/miniconda3.6/envs/pat20201113/lib/python3.6/threading.py", line 916, in _bootstrap_inner
    self.run()
  File "/mnt/cache/share/platform/env/miniconda3.6/envs/pat20201113/lib/python3.6/threading.py", line 864, in run
    self._target(*self._args, **self._kwargs)
  File "/mnt/cache/share/platform/env/miniconda3.6/envs/pat20201113/lib/python3.6/site-packages/autoparrots-1.0rc1+fbf1439-py3.6.egg/autoparrots/schedulers/base_scheduler.py", line 187, in _run_job
    task = pavi_get_task(self.pavi_compare_id, job.id)
  File "/mnt/cache/share/platform/env/miniconda3.6/envs/pat20201113/lib/python3.6/site-packages/autoparrots-1.0rc1+fbf1439-py3.6.egg/autoparrots/utils/pavi_helper.py", line 14, in pavi_get_task
    trainings = compare.get('trainings', [])
AttributeError: 'NoneType' object has no attribute 'get'

Exception in thread Thread-23:
Traceback (most recent call last):
  File "/mnt/cache/share/platform/env/miniconda3.6/envs/pat20201113/lib/python3.6/threading.py", line 916, in _bootstrap_inner
    self.run()
  File "/mnt/cache/share/platform/env/miniconda3.6/envs/pat20201113/lib/python3.6/threading.py", line 864, in run
    self._target(*self._args, **self._kwargs)
  File "/mnt/cache/share/platform/env/miniconda3.6/envs/pat20201113/lib/python3.6/site-packages/autoparrots-1.0rc1+fbf1439-py3.6.egg/autoparrots/schedulers/base_scheduler.py", line 187, in _run_job
    task = pavi_get_task(self.pavi_compare_id, job.id)
  File "/mnt/cache/share/platform/env/miniconda3.6/envs/pat20201113/lib/python3.6/site-packages/autoparrots-1.0rc1+fbf1439-py3.6.egg/autoparrots/utils/pavi_helper.py", line 14, in pavi_get_task
    trainings = compare.get('trainings', [])
AttributeError: 'NoneType' object has no attribute 'get'

Exception in thread Thread-33:
Traceback (most recent call last):
  File "/mnt/cache/share/platform/env/miniconda3.6/envs/pat20201113/lib/python3.6/threading.py", line 916, in _bootstrap_inner
    self.run()
  File "/mnt/cache/share/platform/env/miniconda3.6/envs/pat20201113/lib/python3.6/threading.py", line 864, in run
    self._target(*self._args, **self._kwargs)
  File "/mnt/cache/share/platform/env/miniconda3.6/envs/pat20201113/lib/python3.6/site-packages/autoparrots-1.0rc1+fbf1439-py3.6.egg/autoparrots/schedulers/base_scheduler.py", line 187, in _run_job
    task = pavi_get_task(self.pavi_compare_id, job.id)
  File "/mnt/cache/share/platform/env/miniconda3.6/envs/pat20201113/lib/python3.6/site-packages/autoparrots-1.0rc1+fbf1439-py3.6.egg/autoparrots/utils/pavi_helper.py", line 14, in pavi_get_task
    trainings = compare.get('trainings', [])
AttributeError: 'NoneType' object has no attribute 'get'

2020-11-15 04:59:34,858 ERROR: get_compare error [RequestError: Get http://auth.parrots.sensetime.com/api/v1/session: dial tcp: lookup auth.parrots.sensetime.com on 10.96.0.10:53: read udp 10.244.23.164:42658->10.96.0.10:53: read: connection refused]
Exception in thread Thread-25:
Traceback (most recent call last):
  File "/mnt/cache/share/platform/env/miniconda3.6/envs/pat20201113/lib/python3.6/threading.py", line 916, in _bootstrap_inner
    self.run()
  File "/mnt/cache/share/platform/env/miniconda3.6/envs/pat20201113/lib/python3.6/threading.py", line 864, in run
    self._target(*self._args, **self._kwargs)
  File "/mnt/cache/share/platform/env/miniconda3.6/envs/pat20201113/lib/python3.6/site-packages/autoparrots-1.0rc1+fbf1439-py3.6.egg/autoparrots/schedulers/base_scheduler.py", line 187, in _run_job
    task = pavi_get_task(self.pavi_compare_id, job.id)
  File "/mnt/cache/share/platform/env/miniconda3.6/envs/pat20201113/lib/python3.6/site-packages/autoparrots-1.0rc1+fbf1439-py3.6.egg/autoparrots/utils/pavi_helper.py", line 14, in pavi_get_task
    trainings = compare.get('trainings', [])
AttributeError: 'NoneType' object has no attribute 'get'

2020-11-15 04:59:37,313 ERROR: get_compare error [RequestError: Get http://auth.parrots.sensetime.com/api/v1/session: dial tcp: lookup auth.parrots.sensetime.com on 10.96.0.10:53: read udp 10.244.40.174:46933->10.96.0.10:53: read: connection refused]
2020-11-15 04:59:37,314 ERROR: get_compare error [RequestError: Get http://auth.parrots.sensetime.com/api/v1/session: dial tcp: lookup auth.parrots.sensetime.com on 10.96.0.10:53: read udp 10.244.40.174:46933->10.96.0.10:53: read: connection refused]
2020-11-15 04:59:37,314 ERROR: get_compare error [RequestError: Get http://auth.parrots.sensetime.com/api/v1/session: dial tcp: lookup auth.parrots.sensetime.com on 10.96.0.10:53: read udp 10.244.40.174:46933->10.96.0.10:53: read: connection refused]
2020-11-15 04:59:37,315 ERROR: get_compare error [RequestError: Get http://auth.parrots.sensetime.com/api/v1/session: dial tcp: lookup auth.parrots.sensetime.com on 10.96.0.10:53: read udp 10.244.37.163:47982->10.96.0.10:53: read: connection refused]
2020-11-15 04:59:37,316 ERROR: get_scalar error [RequestError: Get http://auth.parrots.sensetime.com/api/v1/session: dial tcp: lookup auth.parrots.sensetime.com on 10.96.0.10:53: read udp 10.244.37.163:47982->10.96.0.10:53: read: connection refused]
2020-11-15 04:59:37,316 ERROR: get_compare error [RequestError: Get http://auth.parrots.sensetime.com/api/v1/session: dial tcp: lookup auth.parrots.sensetime.com on 10.96.0.10:53: read udp 10.244.40.174:46933->10.96.0.10:53: read: connection refused]
Exception in thread Thread-28:
Traceback (most recent call last):
  File "/mnt/cache/share/platform/env/miniconda3.6/envs/pat20201113/lib/python3.6/threading.py", line 916, in _bootstrap_inner
    self.run()
  File "/mnt/cache/share/platform/env/miniconda3.6/envs/pat20201113/lib/python3.6/threading.py", line 864, in run
    self._target(*self._args, **self._kwargs)
  File "/mnt/cache/share/platform/env/miniconda3.6/envs/pat20201113/lib/python3.6/site-packages/autoparrots-1.0rc1+fbf1439-py3.6.egg/autoparrots/schedulers/base_scheduler.py", line 187, in _run_job
    task = pavi_get_task(self.pavi_compare_id, job.id)
  File "/mnt/cache/share/platform/env/miniconda3.6/envs/pat20201113/lib/python3.6/site-packages/autoparrots-1.0rc1+fbf1439-py3.6.egg/autoparrots/utils/pavi_helper.py", line 14, in pavi_get_task
    trainings = compare.get('trainings', [])
AttributeError: 'NoneType' object has no attribute 'get'

2020-11-15 04:59:37,317 ERROR: get_compare error [RequestError: Get http://auth.parrots.sensetime.com/api/v1/session: dial tcp: lookup auth.parrots.sensetime.com on 10.96.0.10:53: read udp 10.244.37.163:47982->10.96.0.10:53: read: connection refused]
Exception in thread Thread-16:
Traceback (most recent call last):
  File "/mnt/cache/share/platform/env/miniconda3.6/envs/pat20201113/lib/python3.6/threading.py", line 916, in _bootstrap_inner
    self.run()
  File "/mnt/cache/share/platform/env/miniconda3.6/envs/pat20201113/lib/python3.6/threading.py", line 864, in run
    self._target(*self._args, **self._kwargs)
  File "/mnt/cache/share/platform/env/miniconda3.6/envs/pat20201113/lib/python3.6/site-packages/autoparrots-1.0rc1+fbf1439-py3.6.egg/autoparrots/schedulers/base_scheduler.py", line 187, in _run_job
    task = pavi_get_task(self.pavi_compare_id, job.id)
  File "/mnt/cache/share/platform/env/miniconda3.6/envs/pat20201113/lib/python3.6/site-packages/autoparrots-1.0rc1+fbf1439-py3.6.egg/autoparrots/utils/pavi_helper.py", line 14, in pavi_get_task
    trainings = compare.get('trainings', [])
AttributeError: 'NoneType' object has no attribute 'get'

Exception in thread Thread-30:
Traceback (most recent call last):
  File "/mnt/cache/share/platform/env/miniconda3.6/envs/pat20201113/lib/python3.6/threading.py", line 916, in _bootstrap_inner
    self.run()
  File "/mnt/cache/share/platform/env/miniconda3.6/envs/pat20201113/lib/python3.6/threading.py", line 864, in run
    self._target(*self._args, **self._kwargs)
  File "/mnt/cache/share/platform/env/miniconda3.6/envs/pat20201113/lib/python3.6/site-packages/autoparrots-1.0rc1+fbf1439-py3.6.egg/autoparrots/schedulers/base_scheduler.py", line 187, in _run_job
    task = pavi_get_task(self.pavi_compare_id, job.id)
  File "/mnt/cache/share/platform/env/miniconda3.6/envs/pat20201113/lib/python3.6/site-packages/autoparrots-1.0rc1+fbf1439-py3.6.egg/autoparrots/utils/pavi_helper.py", line 14, in pavi_get_task
    trainings = compare.get('trainings', [])
AttributeError: 'NoneType' object has no attribute 'get'

Exception in thread Thread-31:
Traceback (most recent call last):
  File "/mnt/cache/share/platform/env/miniconda3.6/envs/pat20201113/lib/python3.6/threading.py", line 916, in _bootstrap_inner
    self.run()
  File "/mnt/cache/share/platform/env/miniconda3.6/envs/pat20201113/lib/python3.6/threading.py", line 864, in run
    self._target(*self._args, **self._kwargs)
  File "/mnt/cache/share/platform/env/miniconda3.6/envs/pat20201113/lib/python3.6/site-packages/autoparrots-1.0rc1+fbf1439-py3.6.egg/autoparrots/schedulers/base_scheduler.py", line 187, in _run_job
    task = pavi_get_task(self.pavi_compare_id, job.id)
  File "/mnt/cache/share/platform/env/miniconda3.6/envs/pat20201113/lib/python3.6/site-packages/autoparrots-1.0rc1+fbf1439-py3.6.egg/autoparrots/utils/pavi_helper.py", line 14, in pavi_get_task
    trainings = compare.get('trainings', [])
AttributeError: 'NoneType' object has no attribute 'get'

Exception in thread Thread-26:
Traceback (most recent call last):
  File "/mnt/cache/share/platform/env/miniconda3.6/envs/pat20201113/lib/python3.6/threading.py", line 916, in _bootstrap_inner
    self.run()
  File "/mnt/cache/share/platform/env/miniconda3.6/envs/pat20201113/lib/python3.6/threading.py", line 864, in run
    self._target(*self._args, **self._kwargs)
  File "/mnt/cache/share/platform/env/miniconda3.6/envs/pat20201113/lib/python3.6/site-packages/autoparrots-1.0rc1+fbf1439-py3.6.egg/autoparrots/schedulers/base_scheduler.py", line 187, in _run_job
    task = pavi_get_task(self.pavi_compare_id, job.id)
  File "/mnt/cache/share/platform/env/miniconda3.6/envs/pat20201113/lib/python3.6/site-packages/autoparrots-1.0rc1+fbf1439-py3.6.egg/autoparrots/utils/pavi_helper.py", line 14, in pavi_get_task
    trainings = compare.get('trainings', [])
AttributeError: 'NoneType' object has no attribute 'get'

Exception in thread Thread-12:
Traceback (most recent call last):
  File "/mnt/cache/share/platform/env/miniconda3.6/envs/pat20201113/lib/python3.6/threading.py", line 916, in _bootstrap_inner
    self.run()
  File "/mnt/cache/share/platform/env/miniconda3.6/envs/pat20201113/lib/python3.6/threading.py", line 864, in run
    self._target(*self._args, **self._kwargs)
  File "/mnt/cache/share/platform/env/miniconda3.6/envs/pat20201113/lib/python3.6/site-packages/autoparrots-1.0rc1+fbf1439-py3.6.egg/autoparrots/schedulers/base_scheduler.py", line 187, in _run_job
    task = pavi_get_task(self.pavi_compare_id, job.id)
  File "/mnt/cache/share/platform/env/miniconda3.6/envs/pat20201113/lib/python3.6/site-packages/autoparrots-1.0rc1+fbf1439-py3.6.egg/autoparrots/utils/pavi_helper.py", line 14, in pavi_get_task
    trainings = compare.get('trainings', [])
AttributeError: 'NoneType' object has no attribute 'get'

2020-11-15 04:59:37,733 ERROR: get_scalar error [RequestError: Get http://auth.parrots.sensetime.com/api/v1/session: dial tcp: lookup auth.parrots.sensetime.com on 10.96.0.10:53: read udp 10.244.35.242:46680->10.96.0.10:53: read: connection refused]
2020-11-15 04:59:37,734 ERROR: get_scalar error [RequestError: Get http://auth.parrots.sensetime.com/api/v1/session: dial tcp: lookup auth.parrots.sensetime.com on 10.96.0.10:53: read udp 10.244.35.242:46680->10.96.0.10:53: read: connection refused]
2020-11-15 04:59:37,735 ERROR: get_compare error [RequestError: Get http://auth.parrots.sensetime.com/api/v1/session: dial tcp: lookup auth.parrots.sensetime.com on 10.96.0.10:53: read udp 10.244.35.242:46680->10.96.0.10:53: read: connection refused]
2020-11-15 04:59:37,736 ERROR: get_compare error [RequestError: Get http://auth.parrots.sensetime.com/api/v1/session: dial tcp: lookup auth.parrots.sensetime.com on 10.96.0.10:53: read udp 10.244.35.242:46680->10.96.0.10:53: read: connection refused]
2020-11-15 04:59:37,736 ERROR: get_compare error [RequestError: Get http://auth.parrots.sensetime.com/api/v1/session: dial tcp: lookup auth.parrots.sensetime.com on 10.96.0.10:53: read udp 10.244.35.242:46680->10.96.0.10:53: read: connection refused]
2020-11-15 04:59:37,737 ERROR: get_compare error [RequestError: Get http://auth.parrots.sensetime.com/api/v1/session: dial tcp: lookup auth.parrots.sensetime.com on 10.96.0.10:53: read udp 10.244.35.242:46680->10.96.0.10:53: read: connection refused]
2020-11-15 04:59:37,738 ERROR: get_scalar error [RequestError: Get http://auth.parrots.sensetime.com/api/v1/session: dial tcp: lookup auth.parrots.sensetime.com on 10.96.0.10:53: read udp 10.244.35.242:46680->10.96.0.10:53: read: connection refused]
Exception in thread Thread-19:
Traceback (most recent call last):
  File "/mnt/cache/share/platform/env/miniconda3.6/envs/pat20201113/lib/python3.6/threading.py", line 916, in _bootstrap_inner
    self.run()
  File "/mnt/cache/share/platform/env/miniconda3.6/envs/pat20201113/lib/python3.6/threading.py", line 864, in run
    self._target(*self._args, **self._kwargs)
  File "/mnt/cache/share/platform/env/miniconda3.6/envs/pat20201113/lib/python3.6/site-packages/autoparrots-1.0rc1+fbf1439-py3.6.egg/autoparrots/schedulers/base_scheduler.py", line 187, in _run_job
    task = pavi_get_task(self.pavi_compare_id, job.id)
  File "/mnt/cache/share/platform/env/miniconda3.6/envs/pat20201113/lib/python3.6/site-packages/autoparrots-1.0rc1+fbf1439-py3.6.egg/autoparrots/utils/pavi_helper.py", line 14, in pavi_get_task
    trainings = compare.get('trainings', [])
AttributeError: 'NoneType' object has no attribute 'get'

2020-11-15 04:59:37,739 ERROR: get_compare error [RequestError: Get http://auth.parrots.sensetime.com/api/v1/session: dial tcp: lookup auth.parrots.sensetime.com on 10.96.0.10:53: read udp 10.244.35.242:46680->10.96.0.10:53: read: connection refused]
Exception in thread Thread-21:
Traceback (most recent call last):
  File "/mnt/cache/share/platform/env/miniconda3.6/envs/pat20201113/lib/python3.6/threading.py", line 916, in _bootstrap_inner
    self.run()
  File "/mnt/cache/share/platform/env/miniconda3.6/envs/pat20201113/lib/python3.6/threading.py", line 864, in run
    self._target(*self._args, **self._kwargs)
  File "/mnt/cache/share/platform/env/miniconda3.6/envs/pat20201113/lib/python3.6/site-packages/autoparrots-1.0rc1+fbf1439-py3.6.egg/autoparrots/schedulers/base_scheduler.py", line 187, in _run_job
    task = pavi_get_task(self.pavi_compare_id, job.id)
  File "/mnt/cache/share/platform/env/miniconda3.6/envs/pat20201113/lib/python3.6/site-packages/autoparrots-1.0rc1+fbf1439-py3.6.egg/autoparrots/utils/pavi_helper.py", line 14, in pavi_get_task
    trainings = compare.get('trainings', [])
AttributeError: 'NoneType' object has no attribute 'get'

Exception in thread Thread-18:
Traceback (most recent call last):
  File "/mnt/cache/share/platform/env/miniconda3.6/envs/pat20201113/lib/python3.6/threading.py", line 916, in _bootstrap_inner
    self.run()
  File "/mnt/cache/share/platform/env/miniconda3.6/envs/pat20201113/lib/python3.6/threading.py", line 864, in run
    self._target(*self._args, **self._kwargs)
  File "/mnt/cache/share/platform/env/miniconda3.6/envs/pat20201113/lib/python3.6/site-packages/autoparrots-1.0rc1+fbf1439-py3.6.egg/autoparrots/schedulers/base_scheduler.py", line 187, in _run_job
    task = pavi_get_task(self.pavi_compare_id, job.id)
  File "/mnt/cache/share/platform/env/miniconda3.6/envs/pat20201113/lib/python3.6/site-packages/autoparrots-1.0rc1+fbf1439-py3.6.egg/autoparrots/utils/pavi_helper.py", line 14, in pavi_get_task
    trainings = compare.get('trainings', [])
AttributeError: 'NoneType' object has no attribute 'get'

Exception in thread Thread-34:
Traceback (most recent call last):
  File "/mnt/cache/share/platform/env/miniconda3.6/envs/pat20201113/lib/python3.6/threading.py", line 916, in _bootstrap_inner
    self.run()
  File "/mnt/cache/share/platform/env/miniconda3.6/envs/pat20201113/lib/python3.6/threading.py", line 864, in run
    self._target(*self._args, **self._kwargs)
  File "/mnt/cache/share/platform/env/miniconda3.6/envs/pat20201113/lib/python3.6/site-packages/autoparrots-1.0rc1+fbf1439-py3.6.egg/autoparrots/schedulers/base_scheduler.py", line 187, in _run_job
    task = pavi_get_task(self.pavi_compare_id, job.id)
  File "/mnt/cache/share/platform/env/miniconda3.6/envs/pat20201113/lib/python3.6/site-packages/autoparrots-1.0rc1+fbf1439-py3.6.egg/autoparrots/utils/pavi_helper.py", line 14, in pavi_get_task
    trainings = compare.get('trainings', [])
AttributeError: 'NoneType' object has no attribute 'get'

Exception in thread Thread-27:
Traceback (most recent call last):
  File "/mnt/cache/share/platform/env/miniconda3.6/envs/pat20201113/lib/python3.6/threading.py", line 916, in _bootstrap_inner
    self.run()
  File "/mnt/cache/share/platform/env/miniconda3.6/envs/pat20201113/lib/python3.6/threading.py", line 864, in run
    self._target(*self._args, **self._kwargs)
  File "/mnt/cache/share/platform/env/miniconda3.6/envs/pat20201113/lib/python3.6/site-packages/autoparrots-1.0rc1+fbf1439-py3.6.egg/autoparrots/schedulers/base_scheduler.py", line 187, in _run_job
    task = pavi_get_task(self.pavi_compare_id, job.id)
  File "/mnt/cache/share/platform/env/miniconda3.6/envs/pat20201113/lib/python3.6/site-packages/autoparrots-1.0rc1+fbf1439-py3.6.egg/autoparrots/utils/pavi_helper.py", line 14, in pavi_get_task
    trainings = compare.get('trainings', [])
AttributeError: 'NoneType' object has no attribute 'get'

2020-11-15 04:59:42,403 ERROR: get_scalar error [RequestError: Get http://auth.parrots.sensetime.com/api/v1/session: dial tcp: lookup auth.parrots.sensetime.com on 10.96.0.10:53: read udp 10.244.37.163:51502->10.96.0.10:53: read: connection refused]
2020-11-15 04:59:42,404 ERROR: get_scalar error [RequestError: Get http://auth.parrots.sensetime.com/api/v1/session: dial tcp: lookup auth.parrots.sensetime.com on 10.96.0.10:53: read udp 10.244.37.163:51502->10.96.0.10:53: read: connection refused]
2020-11-15 04:59:42,742 ERROR: get_scalar error [RequestError: Get http://auth.parrots.sensetime.com/api/v1/session: dial tcp: lookup auth.parrots.sensetime.com on 10.96.0.10:53: read udp 10.244.35.242:34183->10.96.0.10:53: read: connection refused]
2020-11-15 04:59:45,639 ERROR: get_scalar error [RequestError: Get http://auth.parrots.sensetime.com/api/v1/session: dial tcp: lookup auth.parrots.sensetime.com on 10.96.0.10:53: read udp 10.244.23.164:55146->10.96.0.10:53: read: connection refused]
2020-11-15 04:59:47,357 ERROR: get_scalar error [RequestError: Get http://auth.parrots.sensetime.com/api/v1/session: dial tcp: lookup auth.parrots.sensetime.com on 10.96.0.10:53: read udp 10.244.40.174:44435->10.96.0.10:53: read: connection refused]
2020-11-15 04:59:47,360 ERROR: get_scalar error [RequestError: Get http://auth.parrots.sensetime.com/api/v1/session: dial tcp: lookup auth.parrots.sensetime.com on 10.96.0.10:53: read udp 10.244.40.174:44435->10.96.0.10:53: read: connection refused]
2020-11-15 04:59:47,363 ERROR: get_scalar error [RequestError: Get http://auth.parrots.sensetime.com/api/v1/session: dial tcp: lookup auth.parrots.sensetime.com on 10.96.0.10:53: read udp 10.244.40.174:44435->10.96.0.10:53: read: connection refused]
2020-11-15 04:59:48,118 ERROR: get_scalar error [RequestError: Get http://auth.parrots.sensetime.com/api/v1/session: dial tcp: lookup auth.parrots.sensetime.com on 10.96.0.10:53: read udp 10.244.35.242:36636->10.96.0.10:53: read: connection refused]
2020-11-15 04:59:51,019 ERROR: get_scalar error [RequestError: Get http://auth.parrots.sensetime.com/api/v1/session: dial tcp: lookup auth.parrots.sensetime.com on 10.96.0.10:53: no such host]
2020-11-15 04:59:51,020 ERROR: get_scalar error [RequestError: Get http://auth.parrots.sensetime.com/api/v1/session: dial tcp: lookup auth.parrots.sensetime.com on 10.96.0.10:53: no such host]
2020-11-15 04:59:52,407 ERROR: get_scalar error [RequestError: Get http://auth.parrots.sensetime.com/api/v1/session: dial tcp: lookup auth.parrots.sensetime.com on 10.96.0.10:53: read udp 10.244.40.174:34366->10.96.0.10:53: read: connection refused]
2020-11-15 04:59:57,654 ERROR: get_scalar error [RequestError: Get http://auth.parrots.sensetime.com/api/v1/session: dial tcp: lookup auth.parrots.sensetime.com on 10.96.0.10:53: no such host]
2020-11-15 04:59:57,836 ERROR: get_scalar error [RequestError: ERROR: StatusCode is 401]
2020-11-15 04:59:58,217 ERROR: get_scalar error [RequestError: Forbidden]
2020-11-15 04:59:58,419 ERROR: get_scalar error [RequestError: Forbidden]
2020-11-15 05:00:03,854 ERROR: get_scalar error [RequestError: Forbidden]
2020-11-15 08:10:10,566 log.py                     [line:117] INFO Job(0)[pid: 14749][slurm: 1196252] JobStatus.FINISHED: sh runner/seg/train.sh pat_weeklybuild 16 pspnet --pavi --pavi-project parrots_test_weekly --data_reader MemcachedReader 
              with log: /mnt/lustre/parrots.tester.s.02/parrots_weekly/.search-run/tasks/parrots_test_weekly_20201115_005603/jobs/all/0/log
2020-11-15 08:10:23,574 log.py                     [line:117] INFO Job(0)[pid: 14749, slurm: 1196252] The child process monitoring the log has exited,                       with [job_pid: 14749, job_log_path: /mnt/lustre/parrots.tester.s.02/parrots_weekly/.search-run/tasks/parrots_test_weekly_20201115_005603/jobs/all/0/log, workdir: /mnt/lustre/parrots.tester.s.02/parrots_weekly/.search-run/tasks/parrots_test_weekly_20201115_005603, name: 0, slurm_job_id: 1196252]
2020-11-15 08:31:24,994 log.py                     [line:117] INFO Kill job 5
2020-11-15 08:31:25,026 log.py                     [line:132] ERROR Job(5)[pid: 24531, slurm: 1196257] is killed because the log has not changed for 0.33 hours.
2020-11-15 08:31:25,027 log.py                     [line:117] INFO Job(5)[pid: 24531, slurm: 1196257] The child process monitoring the log has exited,                       with [job_pid: 24531, job_log_path: /mnt/lustre/parrots.tester.s.02/parrots_weekly/.search-run/tasks/parrots_test_weekly_20201115_005603/jobs/all/5/log, workdir: /mnt/lustre/parrots.tester.s.02/parrots_weekly/.search-run/tasks/parrots_test_weekly_20201115_005603, name: 5, slurm_job_id: 1196257]
2020-11-15 22:18:52,259 log.py                     [line:117] INFO Kill job 6
2020-11-15 22:18:52,278 log.py                     [line:132] ERROR Job(6)[pid: 30196, slurm: 1196258] is killed because the log has not changed for 0.33 hours.
2020-11-15 22:18:52,278 log.py                     [line:117] INFO Job(6)[pid: 30196, slurm: 1196258] The child process monitoring the log has exited,                       with [job_pid: 30196, job_log_path: /mnt/lustre/parrots.tester.s.02/parrots_weekly/.search-run/tasks/parrots_test_weekly_20201115_005603/jobs/all/6/log, workdir: /mnt/lustre/parrots.tester.s.02/parrots_weekly/.search-run/tasks/parrots_test_weekly_20201115_005603, name: 6, slurm_job_id: 1196258]
2020-11-16 04:02:39,882 ERROR: get_scalar error [ServerError: Internal error]
2020-11-16 04:02:45,300 ERROR: get_scalar error [ServerError: Internal error]
2020-11-16 04:02:45,301 ERROR: get_scalar error [ServerError: Internal error]
2020-11-16 04:02:46,346 ERROR: get_scalar error [ServerError: Internal error]
2020-11-16 04:02:46,347 ERROR: get_scalar error [ServerError: Internal error]
2020-11-16 04:02:47,391 ERROR: get_scalar error [ServerError: Internal error]
2020-11-16 04:02:47,394 ERROR: get_scalar error [ServerError: Internal error]
2020-11-16 04:02:48,441 ERROR: get_scalar error [ServerError: Internal error]
2020-11-16 04:02:48,444 ERROR: get_scalar error [ServerError: Internal error]
2020-11-16 04:02:49,488 ERROR: get_scalar error [ServerError: Internal error]
2020-11-16 04:02:49,499 ERROR: get_scalar error [ServerError: Internal error]
2020-11-16 04:02:50,535 ERROR: get_scalar error [ServerError: Internal error]
2020-11-16 04:02:50,544 ERROR: get_scalar error [ServerError: Internal error]
2020-11-16 04:02:51,583 ERROR: get_scalar error [ServerError: Internal error]
2020-11-16 04:02:51,587 ERROR: get_scalar error [ServerError: Internal error]
2020-11-16 04:02:52,636 ERROR: get_scalar error [ServerError: Internal error]
2020-11-16 04:02:52,637 ERROR: get_scalar error [ServerError: Internal error]
2020-11-16 04:02:53,682 ERROR: get_scalar error [ServerError: Internal error]
2020-11-16 04:02:53,683 ERROR: get_scalar error [ServerError: Internal error]
2020-11-16 04:02:54,730 ERROR: get_scalar error [ServerError: Internal error]
2020-11-16 04:02:54,731 ERROR: get_scalar error [ServerError: Internal error]
2020-11-16 04:02:55,778 ERROR: get_scalar error [ServerError: Internal error]
2020-11-16 04:02:55,778 ERROR: get_scalar error [ServerError: Internal error]
2020-11-16 04:02:56,827 ERROR: get_scalar error [ServerError: Internal error]
2020-11-16 04:02:56,828 ERROR: get_scalar error [ServerError: Internal error]
2020-11-16 04:02:57,874 ERROR: get_scalar error [ServerError: Internal error]
2020-11-16 04:02:57,878 ERROR: get_scalar error [ServerError: Internal error]
2020-11-16 04:02:58,921 ERROR: get_scalar error [ServerError: Internal error]
2020-11-16 04:02:58,925 ERROR: get_scalar error [ServerError: Internal error]
2020-11-16 04:02:59,967 ERROR: get_scalar error [ServerError: Internal error]
2020-11-16 04:02:59,971 ERROR: get_scalar error [ServerError: Internal error]
2020-11-16 04:03:01,013 ERROR: get_scalar error [ServerError: Internal error]
2020-11-16 04:03:01,017 ERROR: get_scalar error [ServerError: Internal error]
2020-11-16 04:03:02,059 ERROR: get_scalar error [ServerError: Internal error]
2020-11-16 04:03:02,064 ERROR: get_scalar error [ServerError: Internal error]
2020-11-16 04:03:03,107 ERROR: get_scalar error [ServerError: Internal error]
2020-11-16 04:03:03,114 ERROR: get_scalar error [ServerError: Internal error]
2020-11-16 04:03:04,154 ERROR: get_scalar error [ServerError: Internal error]
2020-11-16 04:03:04,160 ERROR: get_scalar error [ServerError: Internal error]
2020-11-16 04:03:05,197 ERROR: get_scalar error [ServerError: Internal error]
2020-11-16 04:03:05,205 ERROR: get_scalar error [ServerError: Internal error]
2020-11-16 04:03:06,244 ERROR: get_scalar error [ServerError: Internal error]
2020-11-16 04:03:06,251 ERROR: get_scalar error [ServerError: Internal error]
2020-11-16 04:03:07,298 ERROR: get_scalar error [ServerError: Internal error]
2020-11-16 04:03:07,299 ERROR: get_scalar error [ServerError: Internal error]
2020-11-16 04:03:08,345 ERROR: get_scalar error [ServerError: Internal error]
2020-11-16 04:03:08,348 ERROR: get_scalar error [ServerError: Internal error]
2020-11-16 04:03:09,392 ERROR: get_scalar error [ServerError: Internal error]
2020-11-16 04:03:09,392 ERROR: get_scalar error [ServerError: Internal error]
2020-11-16 04:03:10,406 ERROR: get_scalar error [ServerError: Internal error]
2020-11-16 04:03:10,439 ERROR: get_scalar error [ServerError: Internal error]
2020-11-16 04:03:10,447 ERROR: get_scalar error [ServerError: Internal error]
2020-11-16 04:03:11,451 ERROR: get_scalar error [ServerError: Internal error]
2020-11-16 04:03:11,486 ERROR: get_scalar error [ServerError: Internal error]
2020-11-16 04:03:11,490 ERROR: get_scalar error [ServerError: Internal error]
2020-11-16 04:03:12,500 ERROR: get_scalar error [ServerError: Internal error]
2020-11-16 04:03:12,532 ERROR: get_scalar error [ServerError: Internal error]
2020-11-16 04:03:12,535 ERROR: get_scalar error [ServerError: Internal error]
2020-11-16 04:03:13,549 ERROR: get_scalar error [ServerError: Internal error]
2020-11-16 04:03:13,578 ERROR: get_scalar error [ServerError: Internal error]
2020-11-16 04:03:13,580 ERROR: get_scalar error [ServerError: Internal error]
2020-11-16 04:03:14,608 ERROR: get_scalar error [ServerError: Internal error]
2020-11-16 04:03:14,625 ERROR: get_scalar error [ServerError: Internal error]
2020-11-16 04:03:14,628 ERROR: get_scalar error [ServerError: Internal error]
2020-11-17 10:29:28,721 log.py                     [line:117] INFO Kill job 7
2020-11-17 10:29:28,745 log.py                     [line:132] ERROR Job(7)[pid: 32405, slurm: 1196259] is killed because the log has not changed for 0.33 hours.
2020-11-17 10:29:28,746 log.py                     [line:117] INFO Job(7)[pid: 32405, slurm: 1196259] The child process monitoring the log has exited,                       with [job_pid: 32405, job_log_path: /mnt/lustre/parrots.tester.s.02/parrots_weekly/.search-run/tasks/parrots_test_weekly_20201115_005603/jobs/all/7/log, workdir: /mnt/lustre/parrots.tester.s.02/parrots_weekly/.search-run/tasks/parrots_test_weekly_20201115_005603, name: 7, slurm_job_id: 1196259]
2020-11-17 10:36:42,802 log.py                     [line:117] INFO Job(3)[pid: 20204][slurm: 1196255] JobStatus.ERROR: sh runner/mmaction/train.sh pat_weeklybuild 8 i3d_r50_video_32x2x1_100e_kinetics400_rgb --pavi --pavi-project parrots_test_weekly --data_reader MemcachedReader --seed 1024 
              with log: /mnt/lustre/parrots.tester.s.02/parrots_weekly/.search-run/tasks/parrots_test_weekly_20201115_005603/jobs/all/3/log
2020-11-17 10:36:47,075 log.py                     [line:117] INFO Job(3)[pid: 20204, slurm: 1196255] The child process monitoring the log has exited,                       with [job_pid: 20204, job_log_path: /mnt/lustre/parrots.tester.s.02/parrots_weekly/.search-run/tasks/parrots_test_weekly_20201115_005603/jobs/all/3/log, workdir: /mnt/lustre/parrots.tester.s.02/parrots_weekly/.search-run/tasks/parrots_test_weekly_20201115_005603, name: 3, slurm_job_id: 1196255]
2020-11-17 11:16:56,946 log.py                     [line:117] INFO Job(1)[pid: 16625][slurm: 1196253] JobStatus.FINISHED: sh runner/example/train.sh pat_weeklybuild 8 mobile_v2_mix --pavi --pavi-project parrots_test_weekly --data_reader MemcachedReader 
              with log: /mnt/lustre/parrots.tester.s.02/parrots_weekly/.search-run/tasks/parrots_test_weekly_20201115_005603/jobs/all/1/log
2020-11-17 11:17:16,524 log.py                     [line:117] INFO Job(1)[pid: 16625, slurm: 1196253] The child process monitoring the log has exited,                       with [job_pid: 16625, job_log_path: /mnt/lustre/parrots.tester.s.02/parrots_weekly/.search-run/tasks/parrots_test_weekly_20201115_005603/jobs/all/1/log, workdir: /mnt/lustre/parrots.tester.s.02/parrots_weekly/.search-run/tasks/parrots_test_weekly_20201115_005603, name: 1, slurm_job_id: 1196253]
2020-11-17 11:30:02,969 log.py                     [line:117] INFO Job(2)[pid: 18424][slurm: 1196254] JobStatus.FINISHED: sh runner/example/train.sh pat_weeklybuild 8 shuffle_v2_mix --pavi --pavi-project parrots_test_weekly --data_reader MemcachedReader 
              with log: /mnt/lustre/parrots.tester.s.02/parrots_weekly/.search-run/tasks/parrots_test_weekly_20201115_005603/jobs/all/2/log
Traceback (most recent call last):
  File "autotest/parrots_test_callback_new.py", line 652, in <module>
    pre_callback_wrapper(config, sys.argv[4], sys.argv[1], sys.argv[2])
  File "autotest/parrots_test_callback_new.py", line 627, in pre_callback_wrapper
    _watch_for_kill_time_limited(framework, model, config)
  File "autotest/parrots_test_callback_new.py", line 125, in _watch_for_kill_time_limited
    info = load_taskinfo(workdir)
  File "/mnt/lustre/share/platform/env/miniconda3.6/envs/pat20201113/lib/python3.6/site-packages/autoparrots-1.0rc1+fbf1439-py3.6.egg/autoparrots/schedulers/naive_scheduler.py", line 32, in load_taskinfo
    return load(os.path.join(workdir, 'task.yaml'), file_format='yaml')
  File "/mnt/lustre/share/platform/env/miniconda3.6/envs/pat20201113/lib/python3.6/site-packages/autoparrots-1.0rc1+fbf1439-py3.6.egg/autoparrots/utils/fileio/io.py", line 42, in load
    obj = handler.load_from_path(file, **kwargs)
  File "/mnt/lustre/share/platform/env/miniconda3.6/envs/pat20201113/lib/python3.6/site-packages/autoparrots-1.0rc1+fbf1439-py3.6.egg/autoparrots/utils/fileio/handlers/base.py", line 21, in load_from_path
    return self.load_from_fileobj(f, **kwargs)
  File "/mnt/lustre/share/platform/env/miniconda3.6/envs/pat20201113/lib/python3.6/site-packages/autoparrots-1.0rc1+fbf1439-py3.6.egg/autoparrots/utils/fileio/handlers/yaml_handler.py", line 46, in load_from_fileobj
    return yaml.load(file, **kwargs)
  File "/mnt/lustre/share/platform/env/miniconda3.6/envs/pat20201113/lib/python3.6/site-packages/yaml/__init__.py", line 114, in load
    return loader.get_single_data()
  File "/mnt/lustre/share/platform/env/miniconda3.6/envs/pat20201113/lib/python3.6/site-packages/yaml/constructor.py", line 49, in get_single_data
    node = self.get_single_node()
  File "/mnt/lustre/share/platform/env/miniconda3.6/envs/pat20201113/lib/python3.6/site-packages/yaml/composer.py", line 36, in get_single_node
    document = self.compose_document()
  File "/mnt/lustre/share/platform/env/miniconda3.6/envs/pat20201113/lib/python3.6/site-packages/yaml/composer.py", line 55, in compose_document
    node = self.compose_node(None, None)
  File "/mnt/lustre/share/platform/env/miniconda3.6/envs/pat20201113/lib/python3.6/site-packages/yaml/composer.py", line 84, in compose_node
    node = self.compose_mapping_node(anchor)
  File "/mnt/lustre/share/platform/env/miniconda3.6/envs/pat20201113/lib/python3.6/site-packages/yaml/composer.py", line 133, in compose_mapping_node
    item_value = self.compose_node(node, item_key)
  File "/mnt/lustre/share/platform/env/miniconda3.6/envs/pat20201113/lib/python3.6/site-packages/yaml/composer.py", line 82, in compose_node
    node = self.compose_sequence_node(anchor)
  File "/mnt/lustre/share/platform/env/miniconda3.6/envs/pat20201113/lib/python3.6/site-packages/yaml/composer.py", line 111, in compose_sequence_node
    node.value.append(self.compose_node(node, index))
  File "/mnt/lustre/share/platform/env/miniconda3.6/envs/pat20201113/lib/python3.6/site-packages/yaml/composer.py", line 84, in compose_node
    node = self.compose_mapping_node(anchor)
  File "/mnt/lustre/share/platform/env/miniconda3.6/envs/pat20201113/lib/python3.6/site-packages/yaml/composer.py", line 127, in compose_mapping_node
    while not self.check_event(MappingEndEvent):
  File "/mnt/lustre/share/platform/env/miniconda3.6/envs/pat20201113/lib/python3.6/site-packages/yaml/parser.py", line 98, in check_event
    self.current_event = self.state()
  File "/mnt/lustre/share/platform/env/miniconda3.6/envs/pat20201113/lib/python3.6/site-packages/yaml/parser.py", line 428, in parse_block_mapping_key
    if self.check_token(KeyToken):
  File "/mnt/lustre/share/platform/env/miniconda3.6/envs/pat20201113/lib/python3.6/site-packages/yaml/scanner.py", line 116, in check_token
    self.fetch_more_tokens()
  File "/mnt/lustre/share/platform/env/miniconda3.6/envs/pat20201113/lib/python3.6/site-packages/yaml/scanner.py", line 173, in fetch_more_tokens
    return self.fetch_stream_end()
  File "/mnt/lustre/share/platform/env/miniconda3.6/envs/pat20201113/lib/python3.6/site-packages/yaml/scanner.py", line 377, in fetch_stream_end
    self.remove_possible_simple_key()
  File "/mnt/lustre/share/platform/env/miniconda3.6/envs/pat20201113/lib/python3.6/site-packages/yaml/scanner.py", line 319, in remove_possible_simple_key
    "could not find expected ':'", self.get_mark())
yaml.scanner.ScannerError: while scanning a simple key
  in "/mnt/lustre/parrots.tester.s.02/parrots_weekly/.search-run/tasks/parrots_test_weekly_20201115_005603/task.yaml", line 263, column 3
could not find expected ':'
  in "/mnt/lustre/parrots.tester.s.02/parrots_weekly/.search-run/tasks/parrots_test_weekly_20201115_005603/task.yaml", line 263, column 5
Traceback (most recent call last):
  File "autotest/parrots_test_callback_new.py", line 652, in <module>
    pre_callback_wrapper(config, sys.argv[4], sys.argv[1], sys.argv[2])
  File "autotest/parrots_test_callback_new.py", line 627, in pre_callback_wrapper
    _watch_for_kill_time_limited(framework, model, config)
  File "autotest/parrots_test_callback_new.py", line 127, in _watch_for_kill_time_limited
    filter(lambda j: j['name'] in [name], info['jobs']))
TypeError: 'NoneType' object is not subscriptable
2020-11-17 11:30:03,140 log.py                     [line:117] INFO Job(2)[pid: 18424, slurm: 1196254] The child process monitoring the log has exited,                       with [job_pid: 18424, job_log_path: /mnt/lustre/parrots.tester.s.02/parrots_weekly/.search-run/tasks/parrots_test_weekly_20201115_005603/jobs/all/2/log, workdir: /mnt/lustre/parrots.tester.s.02/parrots_weekly/.search-run/tasks/parrots_test_weekly_20201115_005603, name: 2, slurm_job_id: 1196254]
2020-11-17 11:30:03,589 log.py                     [line:117] INFO Task parrots_test_weekly_20201115_005603 finished
2020-11-17 15:09:40,683 log.py                     [line:117] INFO Job(4)[pid: 22613, slurm: 1196256] The child process monitoring the log has exited,                       with [job_pid: 22613, job_log_path: /mnt/lustre/parrots.tester.s.02/parrots_weekly/.search-run/tasks/parrots_test_weekly_20201115_005603/jobs/all/4/log, workdir: /mnt/lustre/parrots.tester.s.02/parrots_weekly/.search-run/tasks/parrots_test_weekly_20201115_005603, name: 4, slurm_job_id: 1196256]
2020-11-17 16:43:06,201 log.py                     [line:117] INFO Job(11)[pid: 40644, slurm: 1196264] The child process monitoring the log has exited,                       with [job_pid: 40644, job_log_path: /mnt/lustre/parrots.tester.s.02/parrots_weekly/.search-run/tasks/parrots_test_weekly_20201115_005603/jobs/all/11/log, workdir: /mnt/lustre/parrots.tester.s.02/parrots_weekly/.search-run/tasks/parrots_test_weekly_20201115_005603, name: 11, slurm_job_id: 1196264]
2020-11-17 17:39:06,523 log.py                     [line:117] INFO Job(9)[pid: 36081, slurm: 1196262] The child process monitoring the log has exited,                       with [job_pid: 36081, job_log_path: /mnt/lustre/parrots.tester.s.02/parrots_weekly/.search-run/tasks/parrots_test_weekly_20201115_005603/jobs/all/9/log, workdir: /mnt/lustre/parrots.tester.s.02/parrots_weekly/.search-run/tasks/parrots_test_weekly_20201115_005603, name: 9, slurm_job_id: 1196262]
2020-11-17 22:38:30,268 log.py                     [line:117] INFO Job(12)[pid: 42849, slurm: 1196265] The child process monitoring the log has exited,                       with [job_pid: 42849, job_log_path: /mnt/lustre/parrots.tester.s.02/parrots_weekly/.search-run/tasks/parrots_test_weekly_20201115_005603/jobs/all/12/log, workdir: /mnt/lustre/parrots.tester.s.02/parrots_weekly/.search-run/tasks/parrots_test_weekly_20201115_005603, name: 12, slurm_job_id: 1196265]
2020-11-18 04:55:23,906 log.py                     [line:117] INFO Job(14)[pid: 47364, slurm: 1196267] The child process monitoring the log has exited,                       with [job_pid: 47364, job_log_path: /mnt/lustre/parrots.tester.s.02/parrots_weekly/.search-run/tasks/parrots_test_weekly_20201115_005603/jobs/all/14/log, workdir: /mnt/lustre/parrots.tester.s.02/parrots_weekly/.search-run/tasks/parrots_test_weekly_20201115_005603, name: 14, slurm_job_id: 1196267]
2020-11-18 10:11:23,831 log.py                     [line:117] INFO Job(15)[pid: 49915, slurm: 1196269] The child process monitoring the log has exited,                       with [job_pid: 49915, job_log_path: /mnt/lustre/parrots.tester.s.02/parrots_weekly/.search-run/tasks/parrots_test_weekly_20201115_005603/jobs/all/15/log, workdir: /mnt/lustre/parrots.tester.s.02/parrots_weekly/.search-run/tasks/parrots_test_weekly_20201115_005603, name: 15, slurm_job_id: 1196269]
2020-11-18 16:47:33,228 log.py                     [line:117] INFO Job(19)[pid: 60445, slurm: 1196273] The child process monitoring the log has exited,                       with [job_pid: 60445, job_log_path: /mnt/lustre/parrots.tester.s.02/parrots_weekly/.search-run/tasks/parrots_test_weekly_20201115_005603/jobs/all/19/log, workdir: /mnt/lustre/parrots.tester.s.02/parrots_weekly/.search-run/tasks/parrots_test_weekly_20201115_005603, name: 19, slurm_job_id: 1196273]
2020-11-18 16:57:24,927 log.py                     [line:117] INFO Job(10)[pid: 37962, slurm: 1196263] The child process monitoring the log has exited,                       with [job_pid: 37962, job_log_path: /mnt/lustre/parrots.tester.s.02/parrots_weekly/.search-run/tasks/parrots_test_weekly_20201115_005603/jobs/all/10/log, workdir: /mnt/lustre/parrots.tester.s.02/parrots_weekly/.search-run/tasks/parrots_test_weekly_20201115_005603, name: 10, slurm_job_id: 1196263]
2020-11-18 19:53:29,644 log.py                     [line:117] INFO Job(16)[pid: 52394, slurm: 1196270] The child process monitoring the log has exited,                       with [job_pid: 52394, job_log_path: /mnt/lustre/parrots.tester.s.02/parrots_weekly/.search-run/tasks/parrots_test_weekly_20201115_005603/jobs/all/16/log, workdir: /mnt/lustre/parrots.tester.s.02/parrots_weekly/.search-run/tasks/parrots_test_weekly_20201115_005603, name: 16, slurm_job_id: 1196270]
2020-11-19 00:26:20,778 log.py                     [line:117] INFO Job(20)[pid: 63089, slurm: 1196275] The child process monitoring the log has exited,                       with [job_pid: 63089, job_log_path: /mnt/lustre/parrots.tester.s.02/parrots_weekly/.search-run/tasks/parrots_test_weekly_20201115_005603/jobs/all/20/log, workdir: /mnt/lustre/parrots.tester.s.02/parrots_weekly/.search-run/tasks/parrots_test_weekly_20201115_005603, name: 20, slurm_job_id: 1196275]
2020-11-19 02:39:57,355 log.py                     [line:117] INFO Job(25)[pid: 75942, slurm: 1196283] The child process monitoring the log has exited,                       with [job_pid: 75942, job_log_path: /mnt/lustre/parrots.tester.s.02/parrots_weekly/.search-run/tasks/parrots_test_weekly_20201115_005603/jobs/all/25/log, workdir: /mnt/lustre/parrots.tester.s.02/parrots_weekly/.search-run/tasks/parrots_test_weekly_20201115_005603, name: 25, slurm_job_id: 1196283]
2020-11-19 05:00:34,855 log.py                     [line:117] INFO Job(24)[pid: 73666, slurm: 1196280] The child process monitoring the log has exited,                       with [job_pid: 73666, job_log_path: /mnt/lustre/parrots.tester.s.02/parrots_weekly/.search-run/tasks/parrots_test_weekly_20201115_005603/jobs/all/24/log, workdir: /mnt/lustre/parrots.tester.s.02/parrots_weekly/.search-run/tasks/parrots_test_weekly_20201115_005603, name: 24, slurm_job_id: 1196280]
2020-11-19 09:25:14,434 log.py                     [line:117] INFO Job(22)[pid: 68391, slurm: 1196278] The child process monitoring the log has exited,                       with [job_pid: 68391, job_log_path: /mnt/lustre/parrots.tester.s.02/parrots_weekly/.search-run/tasks/parrots_test_weekly_20201115_005603/jobs/all/22/log, workdir: /mnt/lustre/parrots.tester.s.02/parrots_weekly/.search-run/tasks/parrots_test_weekly_20201115_005603, name: 22, slurm_job_id: 1196278]
2020-11-19 10:49:16,987 log.py                     [line:117] INFO Job(23)[pid: 71089, slurm: 1196279] The child process monitoring the log has exited,                       with [job_pid: 71089, job_log_path: /mnt/lustre/parrots.tester.s.02/parrots_weekly/.search-run/tasks/parrots_test_weekly_20201115_005603/jobs/all/23/log, workdir: /mnt/lustre/parrots.tester.s.02/parrots_weekly/.search-run/tasks/parrots_test_weekly_20201115_005603, name: 23, slurm_job_id: 1196279]
2020-11-19 11:11:53,087 log.py                     [line:117] INFO Job(26)[pid: 78285, slurm: 1196284] The child process monitoring the log has exited,                       with [job_pid: 78285, job_log_path: /mnt/lustre/parrots.tester.s.02/parrots_weekly/.search-run/tasks/parrots_test_weekly_20201115_005603/jobs/all/26/log, workdir: /mnt/lustre/parrots.tester.s.02/parrots_weekly/.search-run/tasks/parrots_test_weekly_20201115_005603, name: 26, slurm_job_id: 1196284]
2020-11-19 18:46:39,029 log.py                     [line:117] INFO Job(27)[pid: 80851, slurm: 1196285] The child process monitoring the log has exited,                       with [job_pid: 80851, job_log_path: /mnt/lustre/parrots.tester.s.02/parrots_weekly/.search-run/tasks/parrots_test_weekly_20201115_005603/jobs/all/27/log, workdir: /mnt/lustre/parrots.tester.s.02/parrots_weekly/.search-run/tasks/parrots_test_weekly_20201115_005603, name: 27, slurm_job_id: 1196285]
2020-11-19 19:22:50,400 log.py                     [line:117] INFO Job(21)[pid: 65738, slurm: 1196276] The child process monitoring the log has exited,                       with [job_pid: 65738, job_log_path: /mnt/lustre/parrots.tester.s.02/parrots_weekly/.search-run/tasks/parrots_test_weekly_20201115_005603/jobs/all/21/log, workdir: /mnt/lustre/parrots.tester.s.02/parrots_weekly/.search-run/tasks/parrots_test_weekly_20201115_005603, name: 21, slurm_job_id: 1196276]
2020-11-19 20:40:44,619 log.py                     [line:117] INFO Job(28)[pid: 87197, slurm: 1196286] The child process monitoring the log has exited,                       with [job_pid: 87197, job_log_path: /mnt/lustre/parrots.tester.s.02/parrots_weekly/.search-run/tasks/parrots_test_weekly_20201115_005603/jobs/all/28/log, workdir: /mnt/lustre/parrots.tester.s.02/parrots_weekly/.search-run/tasks/parrots_test_weekly_20201115_005603, name: 28, slurm_job_id: 1196286]
2020-11-20 01:42:26,111 log.py                     [line:117] INFO Job(29)[pid: 89814, slurm: 1196287] The child process monitoring the log has exited,                       with [job_pid: 89814, job_log_path: /mnt/lustre/parrots.tester.s.02/parrots_weekly/.search-run/tasks/parrots_test_weekly_20201115_005603/jobs/all/29/log, workdir: /mnt/lustre/parrots.tester.s.02/parrots_weekly/.search-run/tasks/parrots_test_weekly_20201115_005603, name: 29, slurm_job_id: 1196287]
2020-11-20 02:16:49,104 log.py                     [line:117] INFO Job(30)[pid: 92610, slurm: 1196292] The child process monitoring the log has exited,                       with [job_pid: 92610, job_log_path: /mnt/lustre/parrots.tester.s.02/parrots_weekly/.search-run/tasks/parrots_test_weekly_20201115_005603/jobs/all/30/log, workdir: /mnt/lustre/parrots.tester.s.02/parrots_weekly/.search-run/tasks/parrots_test_weekly_20201115_005603, name: 30, slurm_job_id: 1196292]
