2019-12-11 11:51:27,259 [32mINFO[0m: Parrots 0.4.0 | Git hash: 4ec10596 | Compute hash: 3ec76b2d[0m
2019-12-11 11:51:27,259 [32mINFO[0m: Parrots 0.4.0 | Git hash: 4ec10596 | Compute hash: 3ec76b2d[0m
2019-12-11 11:51:27,259 [32mINFO[0m: Parrots 0.4.0 | Git hash: 4ec10596 | Compute hash: 3ec76b2d[0m
2019-12-11 11:51:27,259 [32mINFO[0m: Parrots 0.4.0 | Git hash: 4ec10596 | Compute hash: 3ec76b2d[0m
2019-12-11 11:51:27,262 [32mINFO[0m: Parrots 0.4.0 | Git hash: 4ec10596 | Compute hash: 3ec76b2d[0m
2019-12-11 11:51:27,269 [32mINFO[0m: Parrots 0.4.0 | Git hash: 4ec10596 | Compute hash: 3ec76b2d[0m
2019-12-11 11:51:27,275 [32mINFO[0m: Parrots 0.4.0 | Git hash: 4ec10596 | Compute hash: 3ec76b2d[0m
2019-12-11 11:51:27,282 [32mINFO[0m: Parrots 0.4.0 | Git hash: 4ec10596 | Compute hash: 3ec76b2d[0m
2019-12-11 11:52:03,525 [31mERROR[0m: Uncaught exception: 
Traceback (most recent call last):
  File "../tools/main.py", line 291, in <module>
    main()
  File "../tools/main.py", line 65, in main
    rank, global_size, socket.gethostname()), rank=-1)
  File "/mnt/lustre/share/platform/env/miniconda3.6/envs/pat0.4.0rc0/lib/python3.6/logging/__init__.py", line 1308, in info
    self._log(INFO, msg, args, **kwargs)
TypeError: _log() got an unexpected keyword argument 'rank'[0m2019-12-11 11:52:03,525 [31mERROR[0m: Uncaught exception: 
Traceback (most recent call last):
  File "../tools/main.py", line 291, in <module>
    main()
  File "../tools/main.py", line 65, in main
    rank, global_size, socket.gethostname()), rank=-1)
  File "/mnt/lustre/share/platform/env/miniconda3.6/envs/pat0.4.0rc0/lib/python3.6/logging/__init__.py", line 1308, in info
    self._log(INFO, msg, args, **kwargs)
TypeError: _log() got an unexpected keyword argument 'rank'[0m

Traceback (most recent call last):
  File "../tools/main.py", line 291, in <module>
Traceback (most recent call last):
  File "../tools/main.py", line 291, in <module>
2019-12-11 11:52:03,525 [31mERROR[0m: Uncaught exception: 
Traceback (most recent call last):
  File "../tools/main.py", line 291, in <module>
    main()
  File "../tools/main.py", line 65, in main
    rank, global_size, socket.gethostname()), rank=-1)
  File "/mnt/lustre/share/platform/env/miniconda3.6/envs/pat0.4.0rc0/lib/python3.6/logging/__init__.py", line 1308, in info
    self._log(INFO, msg, args, **kwargs)
TypeError: _log() got an unexpected keyword argument 'rank'[0m
Traceback (most recent call last):
  File "../tools/main.py", line 291, in <module>
2019-12-11 11:52:03,525 [31mERROR[0m: Uncaught exception: 
Traceback (most recent call last):
  File "../tools/main.py", line 291, in <module>
    main()
  File "../tools/main.py", line 65, in main
    rank, global_size, socket.gethostname()), rank=-1)
  File "/mnt/lustre/share/platform/env/miniconda3.6/envs/pat0.4.0rc0/lib/python3.6/logging/__init__.py", line 1308, in info
    self._log(INFO, msg, args, **kwargs)
TypeError: _log() got an unexpected keyword argument 'rank'[0m
Traceback (most recent call last):
  File "../tools/main.py", line 291, in <module>
2019-12-11 11:52:03,525 [31mERROR[0m: Uncaught exception: 
Traceback (most recent call last):
  File "../tools/main.py", line 291, in <module>
    main()
  File "../tools/main.py", line 65, in main
    rank, global_size, socket.gethostname()), rank=-1)
  File "/mnt/lustre/share/platform/env/miniconda3.6/envs/pat0.4.0rc0/lib/python3.6/logging/__init__.py", line 1308, in info
    self._log(INFO, msg, args, **kwargs)
TypeError: _log() got an unexpected keyword argument 'rank'[0m
Traceback (most recent call last):
  File "../tools/main.py", line 291, in <module>
    main()
  File "../tools/main.py", line 65, in main
2019-12-11 11:52:03,525 [31mERROR[0m: Uncaught exception: 
Traceback (most recent call last):
  File "../tools/main.py", line 291, in <module>
    main()
  File "../tools/main.py", line 65, in main
    rank, global_size, socket.gethostname()), rank=-1)
  File "/mnt/lustre/share/platform/env/miniconda3.6/envs/pat0.4.0rc0/lib/python3.6/logging/__init__.py", line 1308, in info
    self._log(INFO, msg, args, **kwargs)
TypeError: _log() got an unexpected keyword argument 'rank'[0m
Traceback (most recent call last):
  File "../tools/main.py", line 291, in <module>
    main()
  File "../tools/main.py", line 65, in main
2019-12-11 11:52:03,525 [31mERROR[0m: Uncaught exception: 
Traceback (most recent call last):
  File "../tools/main.py", line 291, in <module>
    main()
  File "../tools/main.py", line 65, in main
    rank, global_size, socket.gethostname()), rank=-1)
  File "/mnt/lustre/share/platform/env/miniconda3.6/envs/pat0.4.0rc0/lib/python3.6/logging/__init__.py", line 1308, in info
    self._log(INFO, msg, args, **kwargs)
TypeError: _log() got an unexpected keyword argument 'rank'[0m
Traceback (most recent call last):
  File "../tools/main.py", line 291, in <module>
    main()
  File "../tools/main.py", line 65, in main
2019-12-11 11:52:03,525 [31mERROR[0m: Uncaught exception: 
Traceback (most recent call last):
  File "../tools/main.py", line 291, in <module>
    main()
  File "../tools/main.py", line 65, in main
    rank, global_size, socket.gethostname()), rank=-1)
  File "/mnt/lustre/share/platform/env/miniconda3.6/envs/pat0.4.0rc0/lib/python3.6/logging/__init__.py", line 1308, in info
    self._log(INFO, msg, args, **kwargs)
TypeError: _log() got an unexpected keyword argument 'rank'[0m
Traceback (most recent call last):
  File "../tools/main.py", line 291, in <module>
    main()
  File "../tools/main.py", line 65, in main
    main()
  File "../tools/main.py", line 65, in main
    rank, global_size, socket.gethostname()), rank=-1)
  File "/mnt/lustre/share/platform/env/miniconda3.6/envs/pat0.4.0rc0/lib/python3.6/logging/__init__.py", line 1308, in info
    main()
  File "../tools/main.py", line 65, in main
    self._log(INFO, msg, args, **kwargs)
TypeError: _log() got an unexpected keyword argument 'rank'
    rank, global_size, socket.gethostname()), rank=-1)
  File "/mnt/lustre/share/platform/env/miniconda3.6/envs/pat0.4.0rc0/lib/python3.6/logging/__init__.py", line 1308, in info
    main()
  File "../tools/main.py", line 65, in main
    self._log(INFO, msg, args, **kwargs)
TypeError: _log() got an unexpected keyword argument 'rank'
    rank, global_size, socket.gethostname()), rank=-1)
  File "/mnt/lustre/share/platform/env/miniconda3.6/envs/pat0.4.0rc0/lib/python3.6/logging/__init__.py", line 1308, in info
    main()
  File "../tools/main.py", line 65, in main
    self._log(INFO, msg, args, **kwargs)
TypeError: _log() got an unexpected keyword argument 'rank'
    rank, global_size, socket.gethostname()), rank=-1)
  File "/mnt/lustre/share/platform/env/miniconda3.6/envs/pat0.4.0rc0/lib/python3.6/logging/__init__.py", line 1308, in info
    rank, global_size, socket.gethostname()), rank=-1)
  File "/mnt/lustre/share/platform/env/miniconda3.6/envs/pat0.4.0rc0/lib/python3.6/logging/__init__.py", line 1308, in info
    self._log(INFO, msg, args, **kwargs)
TypeError: _log() got an unexpected keyword argument 'rank'
    rank, global_size, socket.gethostname()), rank=-1)
  File "/mnt/lustre/share/platform/env/miniconda3.6/envs/pat0.4.0rc0/lib/python3.6/logging/__init__.py", line 1308, in info
    self._log(INFO, msg, args, **kwargs)
TypeError: _log() got an unexpected keyword argument 'rank'
    rank, global_size, socket.gethostname()), rank=-1)
  File "/mnt/lustre/share/platform/env/miniconda3.6/envs/pat0.4.0rc0/lib/python3.6/logging/__init__.py", line 1308, in info
    self._log(INFO, msg, args, **kwargs)
TypeError: _log() got an unexpected keyword argument 'rank'
    rank, global_size, socket.gethostname()), rank=-1)
  File "/mnt/lustre/share/platform/env/miniconda3.6/envs/pat0.4.0rc0/lib/python3.6/logging/__init__.py", line 1308, in info
    self._log(INFO, msg, args, **kwargs)
TypeError: _log() got an unexpected keyword argument 'rank'
    self._log(INFO, msg, args, **kwargs)
TypeError: _log() got an unexpected keyword argument 'rank'
12/11/19 11:52:03.756 (P334905.T334905) [I] parrots exit with unhandled error
12/11/19 11:52:03.757 (P334909.T334909) [I] parrots exit with unhandled error
12/11/19 11:52:03.757 (P334906.T334906) [I] parrots exit with unhandled error
12/11/19 11:52:03.757 (P334908.T334908) [I] parrots exit with unhandled error
12/11/19 11:52:03.757 (P334910.T334910) [I] parrots exit with unhandled error
12/11/19 11:52:03.756 (P334911.T334911) [I] parrots exit with unhandled error
12/11/19 11:52:03.757 (P334907.T334907) [I] parrots exit with unhandled error
12/11/19 11:52:03.756 (P334904.T334904) [I] parrots exit with unhandled error
srun: error: SH-IDC1-10-5-31-38: task 2: Exited with exit code 1
srun: error: SH-IDC1-10-5-31-38: task 4: Exited with exit code 1
srun: error: SH-IDC1-10-5-31-38: tasks 0-1,5-7: Exited with exit code 1
srun: error: SH-IDC1-10-5-31-38: task 3: Exited with exit code 1
